<?xml version="1.0" encoding="utf-8"?>
<!-- =================================================================================== -->
<!-- |    This document was autogenerated by xacro from mbot_with_kinect_gazebo.xacro  | -->
<!-- |    EDITING THIS FILE BY HAND IS NOT RECOMMENDED                                 | -->
<!-- =================================================================================== -->
<robot name="arm">
  <!-- Defining the colors used in this robot -->
  <material name="yellow">
    <color rgba="1 0.4 0 1"/>
  </material>
  <material name="black">
    <color rgba="0 0 0 0.95"/>
  </material>
  <material name="gray">
    <color rgba="0.75 0.75 0.75 1"/>
  </material>
  <!-- kinect -->
  <joint name="kinect_joint" type="fixed">
    <origin rpy="0 0 0" xyz="0.15 0 0.11"/>
    <parent link="base_link"/>
    <child link="kinect_link"/>
  </joint>
  <!-- Create kinect reference frame -->
  <!-- Add mesh for kinect -->
  <link name="kinect_link">
    <origin rpy="0 0 0" xyz="0 0 0"/>
    <visual>
      <origin rpy="0 0 1.5707963" xyz="0 0 0"/>
      <geometry>
        <mesh filename="package://mbot_description/meshes/kinect.dae"/>
      </geometry>
    </visual>
    <collision>
      <geometry>
        <box size="0.07 0.3 0.09"/>
      </geometry>
    </collision>
  </link>
  <joint name="kinect_optical_joint" type="fixed">
    <origin rpy="-1.5708 0 -1.5708" xyz="0 0 0"/>
    <parent link="kinect_link"/>
    <child link="kinect_frame_optical"/>
  </joint>
  <link name="kinect_frame_optical"/>
  <gazebo reference="kinect_link">
    <sensor name="kinect" type="depth">
      <always_on>true</always_on>
      <update_rate>20.0</update_rate>
      <camera>
        <horizontal_fov>1.04719753333</horizontal_fov>
        <image>
          <format>R8G8B8</format>
          <width>640</width>
          <height>480</height>
        </image>
        <clip>
          <near>0.05</near>
          <far>8.0</far>
        </clip>
      </camera>
      <plugin filename="libgazebo_ros_openni_kinect.so" name="kinect_kinect_controller">
        <cameraName>kinect</cameraName>
        <alwaysOn>true</alwaysOn>
        <updateRate>10</updateRate>
        <imageTopicName>rgb/image_raw</imageTopicName>
        <depthImageTopicName>depth/image_raw</depthImageTopicName>
        <pointCloudTopicName>depth/points</pointCloudTopicName>
        <cameraInfoTopicName>rgb/camera_info</cameraInfoTopicName>
        <depthImageCameraInfoTopicName>depth/camera_info</depthImageCameraInfoTopicName>
        <frameName>kinect_frame_optical</frameName>
        <baseline>0.1</baseline>
        <distortion_k1>0.0</distortion_k1>
        <distortion_k2>0.0</distortion_k2>
        <distortion_k3>0.0</distortion_k3>
        <distortion_t1>0.0</distortion_t1>
        <distortion_t2>0.0</distortion_t2>
        <pointCloudCutoff>0.4</pointCloudCutoff>
      </plugin>
    </sensor>
  </gazebo>
  <link name="base_footprint">
    <visual>
      <origin rpy="0 0 0" xyz="0 0 0"/>
      <geometry>
        <box size="0.001 0.001 0.001"/>
      </geometry>
    </visual>
  </link>
  <gazebo reference="base_footprint">
    <turnGravityOff>false</turnGravityOff>
  </gazebo>
  <joint name="base_footprint_joint" type="fixed">
    <origin rpy="0 0 0" xyz="0 0 0.11"/>
    <parent link="base_footprint"/>
    <child link="base_link"/>
  </joint>
  <link name="base_link">
    <visual>
      <origin rpy="0 0 0" xyz=" 0 0 0"/>
      <geometry>
        <cylinder length="0.16" radius="0.2"/>
      </geometry>
      <material name="yellow"/>
    </visual>
    <collision>
      <origin rpy="0 0 0" xyz=" 0 0 0"/>
      <geometry>
        <cylinder length="0.16" radius="0.2"/>
      </geometry>
    </collision>
    <inertial>
      <mass value="20"/>
      <inertia ixx="0.242666666667" ixy="0" ixz="0" iyy="0.242666666667" iyz="0" izz="0.4"/>
    </inertial>
  </link>
  <gazebo reference="base_link">
    <material>Gazebo/Blue</material>
  </gazebo>
  <joint name="left_wheel_joint" type="continuous">
    <origin rpy="0 0 0" xyz="0 -0.19 -0.05"/>
    <parent link="base_link"/>
    <child link="left_wheel_link"/>
    <axis xyz="0 1 0"/>
  </joint>
  <link name="left_wheel_link">
    <visual>
      <origin rpy="1.5707963 0 0" xyz="0 0 0"/>
      <geometry>
        <cylinder length="0.025" radius="0.06"/>
      </geometry>
      <material name="gray"/>
    </visual>
    <collision>
      <origin rpy="1.5707963 0 0" xyz="0 0 0"/>
      <geometry>
        <cylinder length="0.025" radius="0.06"/>
      </geometry>
    </collision>
    <inertial>
      <mass value="2"/>
      <inertia ixx="0.00190416666667" ixy="0" ixz="0" iyy="0.00190416666667" iyz="0" izz="0.0036"/>
    </inertial>
  </link>
  <gazebo reference="left_wheel_link">
    <material>Gazebo/Gray</material>
  </gazebo>
  <!-- Transmission is important to link the joints and the controller -->
  <transmission name="left_wheel_joint_trans">
    <type>transmission_interface/SimpleTransmission</type>
    <joint name="left_wheel_joint">
      <hardwareInterface>hardware_interface/VelocityJointInterface</hardwareInterface>
    </joint>
    <actuator name="left_wheel_joint_motor">
      <hardwareInterface>hardware_interface/VelocityJointInterface</hardwareInterface>
      <mechanicalReduction>1</mechanicalReduction>
    </actuator>
  </transmission>
  <joint name="right_wheel_joint" type="continuous">
    <origin rpy="0 0 0" xyz="0 0.19 -0.05"/>
    <parent link="base_link"/>
    <child link="right_wheel_link"/>
    <axis xyz="0 1 0"/>
  </joint>
  <link name="right_wheel_link">
    <visual>
      <origin rpy="1.5707963 0 0" xyz="0 0 0"/>
      <geometry>
        <cylinder length="0.025" radius="0.06"/>
      </geometry>
      <material name="gray"/>
    </visual>
    <collision>
      <origin rpy="1.5707963 0 0" xyz="0 0 0"/>
      <geometry>
        <cylinder length="0.025" radius="0.06"/>
      </geometry>
    </collision>
    <inertial>
      <mass value="2"/>
      <inertia ixx="0.00190416666667" ixy="0" ixz="0" iyy="0.00190416666667" iyz="0" izz="0.0036"/>
    </inertial>
  </link>
  <gazebo reference="right_wheel_link">
    <material>Gazebo/Gray</material>
  </gazebo>
  <!-- Transmission is important to link the joints and the controller -->
  <transmission name="right_wheel_joint_trans">
    <type>transmission_interface/SimpleTransmission</type>
    <joint name="right_wheel_joint">
      <hardwareInterface>hardware_interface/VelocityJointInterface</hardwareInterface>
    </joint>
    <actuator name="right_wheel_joint_motor">
      <hardwareInterface>hardware_interface/VelocityJointInterface</hardwareInterface>
      <mechanicalReduction>1</mechanicalReduction>
    </actuator>
  </transmission>
  <joint name="front_caster_joint" type="continuous">
    <origin rpy="0 0 0" xyz="-0.18 0 -0.095"/>
    <parent link="base_link"/>
    <child link="front_caster_link"/>
    <axis xyz="0 1 0"/>
  </joint>
  <link name="front_caster_link">
    <visual>
      <origin rpy="0 0 0" xyz="0 0 0"/>
      <geometry>
        <sphere radius="0.015"/>
      </geometry>
      <material name="black"/>
    </visual>
    <collision>
      <origin rpy="0 0 0" xyz="0 0 0"/>
      <geometry>
        <sphere radius="0.015"/>
      </geometry>
    </collision>
    <inertial>
      <mass value="0.5"/>
      <inertia ixx="4.5e-05" ixy="0" ixz="0" iyy="4.5e-05" iyz="0" izz="4.5e-05"/>
    </inertial>
  </link>
  <gazebo reference="front_caster_link">
    <material>Gazebo/Black</material>
  </gazebo>
  <joint name="back_caster_joint" type="continuous">
    <origin rpy="0 0 0" xyz="0.18 0 -0.095"/>
    <parent link="base_link"/>
    <child link="back_caster_link"/>
    <axis xyz="0 1 0"/>
  </joint>
  <link name="back_caster_link">
    <visual>
      <origin rpy="0 0 0" xyz="0 0 0"/>
      <geometry>
        <sphere radius="0.015"/>
      </geometry>
      <material name="black"/>
    </visual>
    <collision>
      <origin rpy="0 0 0" xyz="0 0 0"/>
      <geometry>
        <sphere radius="0.015"/>
      </geometry>
    </collision>
    <inertial>
      <mass value="0.5"/>
      <inertia ixx="4.5e-05" ixy="0" ixz="0" iyy="4.5e-05" iyz="0" izz="4.5e-05"/>
    </inertial>
  </link>
  <gazebo reference="back_caster_link">
    <material>Gazebo/Black</material>
  </gazebo>
  <!-- controller -->
  <gazebo>
    <plugin filename="libgazebo_ros_diff_drive.so" name="differential_drive_controller">
      <rosDebugLevel>Debug</rosDebugLevel>
      <publishWheelTF>true</publishWheelTF>
      <robotNamespace>/</robotNamespace>
      <publishTf>1</publishTf>
      <publishWheelJointState>true</publishWheelJointState>
      <alwaysOn>true</alwaysOn>
      <updateRate>100.0</updateRate>
      <legacyMode>true</legacyMode>
      <leftJoint>left_wheel_joint</leftJoint>
      <rightJoint>right_wheel_joint</rightJoint>
      <wheelSeparation>0.38</wheelSeparation>
      <wheelDiameter>0.12</wheelDiameter>
      <broadcastTF>1</broadcastTF>
      <wheelTorque>30</wheelTorque>
      <wheelAcceleration>1.8</wheelAcceleration>
      <commandTopic>cmd_vel</commandTopic>
      <odometryFrame>odom</odometryFrame>
      <odometryTopic>odom</odometryTopic>
      <robotBaseFrame>base_footprint</robotBaseFrame>
    </plugin>
  </gazebo>
</robot>

